close failed in file object destructor:
IOError: [Errno 9] Bad file descriptor
Traceback (most recent call last):
  File "/opt/genapp/rotdif/bin/main_rotdif.py", line 77, in <module>
    output_res[ 'plot_2d' ] = plot_2d_3d(color_list, exp_keys)[0]
  File "/opt/genapp/rotdif/bin/plot_2d_3d.py", line 311, in plot_2d_3d
    "name"    :  exp_keys[i]
IndexError: list index out of range
